[17/07/2017 05:22] ERROR owner load 73: localhost:27017: [WinError 10061] No connection could be made because the target machine actively refused it
Traceback (most recent call last):
  File "C:\Users\nicos\Desktop\cronanbot\CronanBot\cogs\owner.py", line 64, in load
    self._load_cog(module)
  File "C:\Users\nicos\Desktop\cronanbot\CronanBot\cogs\owner.py", line 932, in _load_cog
    self.bot.load_extension(mod_obj.__name__)
  File "lib\discord\ext\commands\bot.py", line 738, in load_extension
    lib.setup(self)
  File "C:\Users\nicos\Desktop\cronanbot\CronanBot\cogs\leveler.py", line 2986, in setup
    n = Leveler(bot)
  File "C:\Users\nicos\Desktop\cronanbot\CronanBot\cogs\leveler.py", line 60, in __init__
    dbs = client.database_names()
  File "lib\pymongo\mongo_client.py", line 1149, in database_names
    "listDatabases")["databases"]]
  File "lib\pymongo\database.py", line 491, in command
    with client._socket_for_reads(read_preference) as (sock_info, slave_ok):
  File "C:\Users\nicos\AppData\Local\Programs\Python\Python35\lib\contextlib.py", line 59, in __enter__
    return next(self.gen)
  File "lib\pymongo\mongo_client.py", line 859, in _socket_for_reads
    with self._get_socket(read_preference) as sock_info:
  File "C:\Users\nicos\AppData\Local\Programs\Python\Python35\lib\contextlib.py", line 59, in __enter__
    return next(self.gen)
  File "lib\pymongo\mongo_client.py", line 823, in _get_socket
    server = self._get_topology().select_server(selector)
  File "lib\pymongo\topology.py", line 214, in select_server
    address))
  File "lib\pymongo\topology.py", line 189, in select_servers
    self._error_message(selector))
pymongo.errors.ServerSelectionTimeoutError: localhost:27017: [WinError 10061] No connection could be made because the target machine actively refused it
[17/07/2017 05:46] ERROR red load_cogs 575: Expecting ',' delimiter: line 18 column 9 (char 775)
Traceback (most recent call last):
  File "red.py", line 572, in load_cogs
    owner_cog._load_cog(extension)
  File "C:\Users\nicos\Desktop\cronanbot\CronanBot\cogs\owner.py", line 932, in _load_cog
    self.bot.load_extension(mod_obj.__name__)
  File "lib\discord\ext\commands\bot.py", line 738, in load_extension
    lib.setup(self)
  File "C:\Users\nicos\Desktop\cronanbot\CronanBot\cogs\leveler.py", line 2986, in setup
    n = Leveler(bot)
  File "C:\Users\nicos\Desktop\cronanbot\CronanBot\cogs\leveler.py", line 54, in __init__
    self.backgrounds = fileIO("data/leveler/backgrounds.json", "load")
  File "C:\Users\nicos\Desktop\cronanbot\CronanBot\cogs\utils\dataIO.py", line 60, in _legacy_fileio
    return self.load_json(filename)
  File "C:\Users\nicos\Desktop\cronanbot\CronanBot\cogs\utils\dataIO.py", line 32, in load_json
    return self._read_json(filename)
  File "C:\Users\nicos\Desktop\cronanbot\CronanBot\cogs\utils\dataIO.py", line 46, in _read_json
    data = json.load(f)
  File "C:\Users\nicos\AppData\Local\Programs\Python\Python35\lib\json\__init__.py", line 268, in load
    parse_constant=parse_constant, object_pairs_hook=object_pairs_hook, **kw)
  File "C:\Users\nicos\AppData\Local\Programs\Python\Python35\lib\json\__init__.py", line 319, in loads
    return _default_decoder.decode(s)
  File "C:\Users\nicos\AppData\Local\Programs\Python\Python35\lib\json\decoder.py", line 339, in decode
    obj, end = self.raw_decode(s, idx=_w(s, 0).end())
  File "C:\Users\nicos\AppData\Local\Programs\Python\Python35\lib\json\decoder.py", line 355, in raw_decode
    obj, end = self.scan_once(s, idx)
json.decoder.JSONDecodeError: Expecting ',' delimiter: line 18 column 9 (char 775)
[17/07/2017 05:48] ERROR owner load 73: Expecting ',' delimiter: line 18 column 9 (char 775)
Traceback (most recent call last):
  File "C:\Users\nicos\Desktop\cronanbot\CronanBot\cogs\owner.py", line 64, in load
    self._load_cog(module)
  File "C:\Users\nicos\Desktop\cronanbot\CronanBot\cogs\owner.py", line 932, in _load_cog
    self.bot.load_extension(mod_obj.__name__)
  File "lib\discord\ext\commands\bot.py", line 738, in load_extension
    lib.setup(self)
  File "C:\Users\nicos\Desktop\cronanbot\CronanBot\cogs\leveler.py", line 2986, in setup
    n = Leveler(bot)
  File "C:\Users\nicos\Desktop\cronanbot\CronanBot\cogs\leveler.py", line 54, in __init__
    self.backgrounds = fileIO("data/leveler/backgrounds.json", "load")
  File "C:\Users\nicos\Desktop\cronanbot\CronanBot\cogs\utils\dataIO.py", line 60, in _legacy_fileio
    return self.load_json(filename)
  File "C:\Users\nicos\Desktop\cronanbot\CronanBot\cogs\utils\dataIO.py", line 32, in load_json
    return self._read_json(filename)
  File "C:\Users\nicos\Desktop\cronanbot\CronanBot\cogs\utils\dataIO.py", line 46, in _read_json
    data = json.load(f)
  File "C:\Users\nicos\AppData\Local\Programs\Python\Python35\lib\json\__init__.py", line 268, in load
    parse_constant=parse_constant, object_pairs_hook=object_pairs_hook, **kw)
  File "C:\Users\nicos\AppData\Local\Programs\Python\Python35\lib\json\__init__.py", line 319, in loads
    return _default_decoder.decode(s)
  File "C:\Users\nicos\AppData\Local\Programs\Python\Python35\lib\json\decoder.py", line 339, in decode
    obj, end = self.raw_decode(s, idx=_w(s, 0).end())
  File "C:\Users\nicos\AppData\Local\Programs\Python\Python35\lib\json\decoder.py", line 355, in raw_decode
    obj, end = self.scan_once(s, idx)
json.decoder.JSONDecodeError: Expecting ',' delimiter: line 18 column 9 (char 775)
[17/07/2017 05:49] ERROR owner load 73: Expecting ',' delimiter: line 18 column 9 (char 775)
Traceback (most recent call last):
  File "C:\Users\nicos\Desktop\cronanbot\CronanBot\cogs\owner.py", line 64, in load
    self._load_cog(module)
  File "C:\Users\nicos\Desktop\cronanbot\CronanBot\cogs\owner.py", line 932, in _load_cog
    self.bot.load_extension(mod_obj.__name__)
  File "lib\discord\ext\commands\bot.py", line 738, in load_extension
    lib.setup(self)
  File "C:\Users\nicos\Desktop\cronanbot\CronanBot\cogs\leveler.py", line 2986, in setup
    n = Leveler(bot)
  File "C:\Users\nicos\Desktop\cronanbot\CronanBot\cogs\leveler.py", line 54, in __init__
    self.backgrounds = fileIO("data/leveler/backgrounds.json", "load")
  File "C:\Users\nicos\Desktop\cronanbot\CronanBot\cogs\utils\dataIO.py", line 60, in _legacy_fileio
    return self.load_json(filename)
  File "C:\Users\nicos\Desktop\cronanbot\CronanBot\cogs\utils\dataIO.py", line 32, in load_json
    return self._read_json(filename)
  File "C:\Users\nicos\Desktop\cronanbot\CronanBot\cogs\utils\dataIO.py", line 46, in _read_json
    data = json.load(f)
  File "C:\Users\nicos\AppData\Local\Programs\Python\Python35\lib\json\__init__.py", line 268, in load
    parse_constant=parse_constant, object_pairs_hook=object_pairs_hook, **kw)
  File "C:\Users\nicos\AppData\Local\Programs\Python\Python35\lib\json\__init__.py", line 319, in loads
    return _default_decoder.decode(s)
  File "C:\Users\nicos\AppData\Local\Programs\Python\Python35\lib\json\decoder.py", line 339, in decode
    obj, end = self.raw_decode(s, idx=_w(s, 0).end())
  File "C:\Users\nicos\AppData\Local\Programs\Python\Python35\lib\json\decoder.py", line 355, in raw_decode
    obj, end = self.scan_once(s, idx)
json.decoder.JSONDecodeError: Expecting ',' delimiter: line 18 column 9 (char 775)
[17/07/2017 06:26] ERROR red on_command_error 371: Exception in command 'badge give'
Traceback (most recent call last):
  File "lib\discord\ext\commands\core.py", line 50, in wrapped
    ret = yield from coro(*args, **kwargs)
  File "C:\Users\nicos\Desktop\cronanbot\CronanBot\cogs\leveler.py", line 1569, in give
    badges = serverbadges['badges']
TypeError: 'NoneType' object is not subscriptable
[17/07/2017 06:59] ERROR red on_command_error 371: Exception in command 'badge give'
Traceback (most recent call last):
  File "lib\discord\ext\commands\core.py", line 50, in wrapped
    ret = yield from coro(*args, **kwargs)
  File "C:\Users\nicos\Desktop\cronanbot\CronanBot\cogs\leveler.py", line 1569, in give
    badges = serverbadges['badges']
TypeError: 'NoneType' object is not subscriptable
[17/07/2017 09:03] ERROR red on_command_error 371: Exception in command 'cog install'
Traceback (most recent call last):
  File "lib\discord\ext\commands\core.py", line 50, in wrapped
    ret = yield from coro(*args, **kwargs)
  File "C:\Users\nicos\Desktop\cronanbot\CronanBot\cogs\downloader.py", line 407, in _install
    await owner.load.callback(owner, cog_name=cog)
AttributeError: 'function' object has no attribute 'callback'
[17/07/2017 09:07] ERROR red on_command_error 371: Exception in command 'msgvote downemoji'
Traceback (most recent call last):
  File "lib\discord\ext\commands\core.py", line 50, in wrapped
    ret = yield from coro(*args, **kwargs)
  File "C:\Users\nicos\Desktop\cronanbot\CronanBot\cogs\msgvote.py", line 83, in _msgvote_downemoji
    emoji = str(self.fix_custom_emoji(ctx.message.server, emoji))
  File "C:\Users\nicos\Desktop\cronanbot\CronanBot\cogs\msgvote.py", line 122, in fix_custom_emoji
    return [r for r in server.emojis if r.name == emoji.split(':')[1]][0]
IndexError: list index out of range
[17/07/2017 14:51] ERROR red load_cogs 575: localhost:27017: [WinError 10061] No connection could be made because the target machine actively refused it
Traceback (most recent call last):
  File "red.py", line 572, in load_cogs
    owner_cog._load_cog(extension)
  File "C:\Users\nicos\Desktop\cronanbot\CronanBot\cogs\owner.py", line 930, in _load_cog
    self.bot.load_extension(mod_obj.__name__)
  File "lib\discord\ext\commands\bot.py", line 738, in load_extension
    lib.setup(self)
  File "C:\Users\nicos\Desktop\cronanbot\CronanBot\cogs\leveler.py", line 2986, in setup
    n = Leveler(bot)
  File "C:\Users\nicos\Desktop\cronanbot\CronanBot\cogs\leveler.py", line 60, in __init__
    dbs = client.database_names()
  File "lib\pymongo\mongo_client.py", line 1149, in database_names
    "listDatabases")["databases"]]
  File "lib\pymongo\database.py", line 491, in command
    with client._socket_for_reads(read_preference) as (sock_info, slave_ok):
  File "C:\Users\nicos\AppData\Local\Programs\Python\Python35\lib\contextlib.py", line 59, in __enter__
    return next(self.gen)
  File "lib\pymongo\mongo_client.py", line 859, in _socket_for_reads
    with self._get_socket(read_preference) as sock_info:
  File "C:\Users\nicos\AppData\Local\Programs\Python\Python35\lib\contextlib.py", line 59, in __enter__
    return next(self.gen)
  File "lib\pymongo\mongo_client.py", line 823, in _get_socket
    server = self._get_topology().select_server(selector)
  File "lib\pymongo\topology.py", line 214, in select_server
    address))
  File "lib\pymongo\topology.py", line 189, in select_servers
    self._error_message(selector))
pymongo.errors.ServerSelectionTimeoutError: localhost:27017: [WinError 10061] No connection could be made because the target machine actively refused it
[17/07/2017 15:59] ERROR red load_cogs 575: ('invalid syntax', ('C:\\Users\\nicos\\Desktop\\cronanbot\\CronanBot\\cogs\\fidget.py', 37, 93, '        message = f"{ctx.author.mention} spun a fidget spinner; let\'s see how long it lasts."\n'))
Traceback (most recent call last):
  File "C:\Users\nicos\Desktop\cronanbot\CronanBot\cogs\owner.py", line 931, in _load_cog
    mod_obj = importlib.import_module(cogname)
  File "C:\Users\nicos\AppData\Local\Programs\Python\Python35\lib\importlib\__init__.py", line 126, in import_module
    return _bootstrap._gcd_import(name[level:], package, level)
  File "<frozen importlib._bootstrap>", line 986, in _gcd_import
  File "<frozen importlib._bootstrap>", line 969, in _find_and_load
  File "<frozen importlib._bootstrap>", line 958, in _find_and_load_unlocked
  File "<frozen importlib._bootstrap>", line 673, in _load_unlocked
  File "<frozen importlib._bootstrap_external>", line 658, in exec_module
  File "<frozen importlib._bootstrap_external>", line 764, in get_code
  File "<frozen importlib._bootstrap_external>", line 724, in source_to_code
  File "<frozen importlib._bootstrap>", line 222, in _call_with_frames_removed
  File "C:\Users\nicos\Desktop\cronanbot\CronanBot\cogs\fidget.py", line 37
    message = f"{ctx.author.mention} spun a fidget spinner; let's see how long it lasts."
                                                                                        ^
SyntaxError: invalid syntax

During handling of the above exception, another exception occurred:

Traceback (most recent call last):
  File "red.py", line 572, in load_cogs
    owner_cog._load_cog(extension)
  File "C:\Users\nicos\Desktop\cronanbot\CronanBot\cogs\owner.py", line 935, in _load_cog
    raise CogLoadError(*e.args)
cogs.owner.CogLoadError: ('invalid syntax', ('C:\\Users\\nicos\\Desktop\\cronanbot\\CronanBot\\cogs\\fidget.py', 37, 93, '        message = f"{ctx.author.mention} spun a fidget spinner; let\'s see how long it lasts."\n'))
[17/07/2017 16:04] ERROR red load_cogs 575: No module named 'utils'
Traceback (most recent call last):
  File "red.py", line 572, in load_cogs
    owner_cog._load_cog(extension)
  File "C:\Users\nicos\Desktop\cronanbot\CronanBot\cogs\owner.py", line 931, in _load_cog
    mod_obj = importlib.import_module(cogname)
  File "C:\Users\nicos\AppData\Local\Programs\Python\Python35\lib\importlib\__init__.py", line 126, in import_module
    return _bootstrap._gcd_import(name[level:], package, level)
  File "<frozen importlib._bootstrap>", line 986, in _gcd_import
  File "<frozen importlib._bootstrap>", line 969, in _find_and_load
  File "<frozen importlib._bootstrap>", line 958, in _find_and_load_unlocked
  File "<frozen importlib._bootstrap>", line 673, in _load_unlocked
  File "<frozen importlib._bootstrap_external>", line 662, in exec_module
  File "<frozen importlib._bootstrap>", line 222, in _call_with_frames_removed
  File "C:\Users\nicos\Desktop\cronanbot\CronanBot\cogs\fidget.py", line 10, in <module>
    import utils.helpers
ImportError: No module named 'utils'
[17/07/2017 16:08] ERROR red on_command_error 371: Exception in command 'help'
Traceback (most recent call last):
  File "lib\discord\ext\commands\core.py", line 50, in wrapped
    ret = yield from coro(*args, **kwargs)
  File "lib\discord\ext\commands\bot.py", line 102, in _default_help_command
    pages = bot.formatter.format_help_for(ctx, bot)
  File "lib\discord\ext\commands\formatter.py", line 291, in format_help_for
    return self.format()
  File "lib\discord\ext\commands\formatter.py", line 336, in format
    data = sorted(self.filter_command_list(), key=category)
  File "lib\discord\ext\commands\formatter.py", line 255, in predicate
    return cmd.can_run(self.context) and self.context.bot.can_run(self.context)
  File "lib\discord\ext\commands\core.py", line 438, in can_run
    return all(predicate(context) for predicate in predicates)
  File "lib\discord\ext\commands\core.py", line 438, in <genexpr>
    return all(predicate(context) for predicate in predicates)
  File "C:\Users\nicos\Desktop\cronanbot\CronanBot\cogs\fidget.py", line 22, in is_not_spinning
    if ctx.author.id in spinners:
AttributeError: 'Context' object has no attribute 'author'
[17/07/2017 16:14] ERROR red on_command_error 371: Exception in command 'help'
Traceback (most recent call last):
  File "lib\discord\ext\commands\core.py", line 50, in wrapped
    ret = yield from coro(*args, **kwargs)
  File "lib\discord\ext\commands\bot.py", line 102, in _default_help_command
    pages = bot.formatter.format_help_for(ctx, bot)
  File "lib\discord\ext\commands\formatter.py", line 291, in format_help_for
    return self.format()
  File "lib\discord\ext\commands\formatter.py", line 336, in format
    data = sorted(self.filter_command_list(), key=category)
  File "lib\discord\ext\commands\formatter.py", line 255, in predicate
    return cmd.can_run(self.context) and self.context.bot.can_run(self.context)
  File "lib\discord\ext\commands\core.py", line 438, in can_run
    return all(predicate(context) for predicate in predicates)
  File "lib\discord\ext\commands\core.py", line 438, in <genexpr>
    return all(predicate(context) for predicate in predicates)
  File "C:\Users\nicos\Desktop\cronanbot\CronanBot\cogs\fidget.py", line 22, in is_not_spinning
    if discord.user.id in spinners:
NameError: name 'discord' is not defined
[17/07/2017 16:18] ERROR red on_command_error 371: Exception in command 'help'
Traceback (most recent call last):
  File "lib\discord\ext\commands\core.py", line 50, in wrapped
    ret = yield from coro(*args, **kwargs)
  File "lib\discord\ext\commands\bot.py", line 102, in _default_help_command
    pages = bot.formatter.format_help_for(ctx, bot)
  File "lib\discord\ext\commands\formatter.py", line 291, in format_help_for
    return self.format()
  File "lib\discord\ext\commands\formatter.py", line 336, in format
    data = sorted(self.filter_command_list(), key=category)
  File "lib\discord\ext\commands\formatter.py", line 255, in predicate
    return cmd.can_run(self.context) and self.context.bot.can_run(self.context)
  File "lib\discord\ext\commands\core.py", line 438, in can_run
    return all(predicate(context) for predicate in predicates)
  File "lib\discord\ext\commands\core.py", line 438, in <genexpr>
    return all(predicate(context) for predicate in predicates)
  File "C:\Users\nicos\Desktop\cronanbot\CronanBot\cogs\fidget.py", line 22, in is_not_spinning
    if ctx.user.id in spinners:
AttributeError: 'Context' object has no attribute 'user'
[17/07/2017 16:20] ERROR red on_command_error 371: Exception in command 'help'
Traceback (most recent call last):
  File "lib\discord\ext\commands\core.py", line 50, in wrapped
    ret = yield from coro(*args, **kwargs)
  File "lib\discord\ext\commands\bot.py", line 102, in _default_help_command
    pages = bot.formatter.format_help_for(ctx, bot)
  File "lib\discord\ext\commands\formatter.py", line 291, in format_help_for
    return self.format()
  File "lib\discord\ext\commands\formatter.py", line 336, in format
    data = sorted(self.filter_command_list(), key=category)
  File "lib\discord\ext\commands\formatter.py", line 255, in predicate
    return cmd.can_run(self.context) and self.context.bot.can_run(self.context)
  File "lib\discord\ext\commands\core.py", line 438, in can_run
    return all(predicate(context) for predicate in predicates)
  File "lib\discord\ext\commands\core.py", line 438, in <genexpr>
    return all(predicate(context) for predicate in predicates)
  File "C:\Users\nicos\Desktop\cronanbot\CronanBot\cogs\fidget.py", line 23, in is_not_spinning
    if ctx.user.id in spinners:
AttributeError: 'Context' object has no attribute 'user'
[17/07/2017 16:26] ERROR red load_cogs 575: name 'ctx' is not defined
Traceback (most recent call last):
  File "red.py", line 572, in load_cogs
    owner_cog._load_cog(extension)
  File "C:\Users\nicos\Desktop\cronanbot\CronanBot\cogs\owner.py", line 931, in _load_cog
    mod_obj = importlib.import_module(cogname)
  File "C:\Users\nicos\AppData\Local\Programs\Python\Python35\lib\importlib\__init__.py", line 126, in import_module
    return _bootstrap._gcd_import(name[level:], package, level)
  File "<frozen importlib._bootstrap>", line 986, in _gcd_import
  File "<frozen importlib._bootstrap>", line 969, in _find_and_load
  File "<frozen importlib._bootstrap>", line 958, in _find_and_load_unlocked
  File "<frozen importlib._bootstrap>", line 673, in _load_unlocked
  File "<frozen importlib._bootstrap_external>", line 662, in exec_module
  File "<frozen importlib._bootstrap>", line 222, in _call_with_frames_removed
  File "C:\Users\nicos\Desktop\cronanbot\CronanBot\cogs\fidget.py", line 14, in <module>
    user = ctx.message.author
NameError: name 'ctx' is not defined
[17/07/2017 16:27] ERROR red load_cogs 575: name 'ctx' is not defined
Traceback (most recent call last):
  File "red.py", line 572, in load_cogs
    owner_cog._load_cog(extension)
  File "C:\Users\nicos\Desktop\cronanbot\CronanBot\cogs\owner.py", line 931, in _load_cog
    mod_obj = importlib.import_module(cogname)
  File "C:\Users\nicos\AppData\Local\Programs\Python\Python35\lib\importlib\__init__.py", line 126, in import_module
    return _bootstrap._gcd_import(name[level:], package, level)
  File "<frozen importlib._bootstrap>", line 986, in _gcd_import
  File "<frozen importlib._bootstrap>", line 969, in _find_and_load
  File "<frozen importlib._bootstrap>", line 958, in _find_and_load_unlocked
  File "<frozen importlib._bootstrap>", line 673, in _load_unlocked
  File "<frozen importlib._bootstrap_external>", line 662, in exec_module
  File "<frozen importlib._bootstrap>", line 222, in _call_with_frames_removed
  File "C:\Users\nicos\Desktop\cronanbot\CronanBot\cogs\fidget.py", line 28, in <module>
    class Fidget:
  File "C:\Users\nicos\Desktop\cronanbot\CronanBot\cogs\fidget.py", line 31, in Fidget
    user = ctx.message.author
NameError: name 'ctx' is not defined
[17/07/2017 16:29] ERROR red on_command_error 371: Exception in command 'spinner'
Traceback (most recent call last):
  File "lib\discord\ext\commands\core.py", line 50, in wrapped
    ret = yield from coro(*args, **kwargs)
  File "C:\Users\nicos\Desktop\cronanbot\CronanBot\cogs\fidget.py", line 36, in spinner
    user = ctx.message.author
AttributeError: 'str' object has no attribute 'message'
[17/07/2017 16:31] ERROR red on_command_error 371: Exception in command 'spinner'
Traceback (most recent call last):
  File "lib\discord\ext\commands\core.py", line 50, in wrapped
    ret = yield from coro(*args, **kwargs)
  File "C:\Users\nicos\Desktop\cronanbot\CronanBot\cogs\fidget.py", line 36, in spinner
    user = ctx.message.author
AttributeError: 'str' object has no attribute 'message'
[17/07/2017 16:35] ERROR red on_command_error 371: Exception in command 'help'
Traceback (most recent call last):
  File "lib\discord\ext\commands\core.py", line 50, in wrapped
    ret = yield from coro(*args, **kwargs)
  File "lib\discord\ext\commands\bot.py", line 102, in _default_help_command
    pages = bot.formatter.format_help_for(ctx, bot)
  File "lib\discord\ext\commands\formatter.py", line 291, in format_help_for
    return self.format()
  File "lib\discord\ext\commands\formatter.py", line 336, in format
    data = sorted(self.filter_command_list(), key=category)
  File "lib\discord\ext\commands\formatter.py", line 255, in predicate
    return cmd.can_run(self.context) and self.context.bot.can_run(self.context)
  File "lib\discord\ext\commands\core.py", line 438, in can_run
    return all(predicate(context) for predicate in predicates)
  File "lib\discord\ext\commands\core.py", line 438, in <genexpr>
    return all(predicate(context) for predicate in predicates)
  File "C:\Users\nicos\Desktop\cronanbot\CronanBot\cogs\fidget.py", line 23, in is_not_spinning
    if self.user.id in spinners:
AttributeError: 'Context' object has no attribute 'user'
[17/07/2017 16:36] ERROR red on_command_error 371: Exception in command 'help'
Traceback (most recent call last):
  File "lib\discord\ext\commands\core.py", line 50, in wrapped
    ret = yield from coro(*args, **kwargs)
  File "lib\discord\ext\commands\bot.py", line 102, in _default_help_command
    pages = bot.formatter.format_help_for(ctx, bot)
  File "lib\discord\ext\commands\formatter.py", line 291, in format_help_for
    return self.format()
  File "lib\discord\ext\commands\formatter.py", line 336, in format
    data = sorted(self.filter_command_list(), key=category)
  File "lib\discord\ext\commands\formatter.py", line 255, in predicate
    return cmd.can_run(self.context) and self.context.bot.can_run(self.context)
  File "lib\discord\ext\commands\core.py", line 438, in can_run
    return all(predicate(context) for predicate in predicates)
  File "lib\discord\ext\commands\core.py", line 438, in <genexpr>
    return all(predicate(context) for predicate in predicates)
  File "C:\Users\nicos\Desktop\cronanbot\CronanBot\cogs\fidget.py", line 24, in is_not_spinning
    if self.user.id in spinners:
AttributeError: 'Context' object has no attribute 'user'
[17/07/2017 16:37] ERROR red on_command_error 371: Exception in command 'help'
Traceback (most recent call last):
  File "lib\discord\ext\commands\core.py", line 50, in wrapped
    ret = yield from coro(*args, **kwargs)
  File "lib\discord\ext\commands\bot.py", line 102, in _default_help_command
    pages = bot.formatter.format_help_for(ctx, bot)
  File "lib\discord\ext\commands\formatter.py", line 291, in format_help_for
    return self.format()
  File "lib\discord\ext\commands\formatter.py", line 336, in format
    data = sorted(self.filter_command_list(), key=category)
  File "lib\discord\ext\commands\formatter.py", line 255, in predicate
    return cmd.can_run(self.context) and self.context.bot.can_run(self.context)
  File "lib\discord\ext\commands\core.py", line 438, in can_run
    return all(predicate(context) for predicate in predicates)
  File "lib\discord\ext\commands\core.py", line 438, in <genexpr>
    return all(predicate(context) for predicate in predicates)
  File "C:\Users\nicos\Desktop\cronanbot\CronanBot\cogs\fidget.py", line 24, in is_not_spinning
    if self.user.id in spinners:
AttributeError: 'Context' object has no attribute 'user'
[17/07/2017 16:47] ERROR red <module> 636: Fatal exception, attempting graceful logout
Traceback (most recent call last):
  File "lib\aiohttp\connector.py", line 601, in _create_direct_connection
    local_addr=self._local_addr)
  File "C:\Users\nicos\AppData\Local\Programs\Python\Python35\lib\asyncio\base_events.py", line 645, in create_connection
    raise exceptions[0]
  File "C:\Users\nicos\AppData\Local\Programs\Python\Python35\lib\asyncio\base_events.py", line 632, in create_connection
    yield from self.sock_connect(sock, address)
  File "C:\Users\nicos\AppData\Local\Programs\Python\Python35\lib\asyncio\futures.py", line 358, in __iter__
    yield self  # This tells Task to wait for completion.
  File "C:\Users\nicos\AppData\Local\Programs\Python\Python35\lib\asyncio\tasks.py", line 290, in _wakeup
    future.result()
  File "C:\Users\nicos\AppData\Local\Programs\Python\Python35\lib\asyncio\futures.py", line 274, in result
    raise self._exception
  File "C:\Users\nicos\AppData\Local\Programs\Python\Python35\lib\asyncio\selector_events.py", line 436, in _sock_connect_cb
    raise OSError(err, 'Connect call failed %s' % (address,))
OSError: [Errno 10065] Connect call failed ('104.16.59.5', 443)

The above exception was the direct cause of the following exception:

Traceback (most recent call last):
  File "lib\aiohttp\connector.py", line 304, in connect
    yield from self._create_connection(req)
  File "lib\aiohttp\connector.py", line 578, in _create_connection
    transport, proto = yield from self._create_direct_connection(req)
  File "lib\aiohttp\connector.py", line 624, in _create_direct_connection
    (req.host, req.port, exc.strerror)) from exc
aiohttp.errors.ClientOSError: [Errno 10065] Can not connect to discordapp.com:443 [Connect call failed ('104.16.59.5', 443)]

The above exception was the direct cause of the following exception:

Traceback (most recent call last):
  File "red.py", line 616, in <module>
    loop.run_until_complete(main(bot))
  File "C:\Users\nicos\AppData\Local\Programs\Python\Python35\lib\asyncio\base_events.py", line 337, in run_until_complete
    return future.result()
  File "C:\Users\nicos\AppData\Local\Programs\Python\Python35\lib\asyncio\futures.py", line 274, in result
    raise self._exception
  File "C:\Users\nicos\AppData\Local\Programs\Python\Python35\lib\asyncio\tasks.py", line 241, in _step
    result = coro.throw(exc)
  File "red.py", line 605, in main
    yield from bot.connect()
  File "lib\discord\client.py", line 452, in connect
    self.ws = yield from DiscordWebSocket.from_client(self, resume=resume)
  File "lib\discord\gateway.py", line 203, in from_client
    gateway = yield from client.http.get_gateway()
  File "lib\discord\http.py", line 633, in get_gateway
    data = yield from self.request(Route('GET', '/gateway'))
  File "lib\discord\http.py", line 137, in request
    r = yield from self.session.request(method, url, **kwargs)
  File "lib\aiohttp\client.py", line 555, in __iter__
    resp = yield from self._coro
  File "lib\aiohttp\client.py", line 198, in _request
    conn = yield from self._connector.connect(req)
  File "lib\aiohttp\connector.py", line 314, in connect
    .format(key, exc.strerror)) from exc
aiohttp.errors.ClientOSError: [Errno 10065] Cannot connect to host discordapp.com:443 ssl:True [Can not connect to discordapp.com:443 [Connect call failed ('104.16.59.5', 443)]]
[17/07/2017 16:54] ERROR red load_cogs 575: ('invalid syntax', ('C:\\Users\\nicos\\Desktop\\cronanbot\\CronanBot\\cogs\\fidget.py', 40, 59, '        await send_file(message.channel, FIDGET_SPINNERS,*, filename=None, content=message, tts=False)\n'))
Traceback (most recent call last):
  File "C:\Users\nicos\Desktop\cronanbot\CronanBot\cogs\owner.py", line 931, in _load_cog
    mod_obj = importlib.import_module(cogname)
  File "C:\Users\nicos\AppData\Local\Programs\Python\Python35\lib\importlib\__init__.py", line 126, in import_module
    return _bootstrap._gcd_import(name[level:], package, level)
  File "<frozen importlib._bootstrap>", line 986, in _gcd_import
  File "<frozen importlib._bootstrap>", line 969, in _find_and_load
  File "<frozen importlib._bootstrap>", line 958, in _find_and_load_unlocked
  File "<frozen importlib._bootstrap>", line 673, in _load_unlocked
  File "<frozen importlib._bootstrap_external>", line 658, in exec_module
  File "<frozen importlib._bootstrap_external>", line 764, in get_code
  File "<frozen importlib._bootstrap_external>", line 724, in source_to_code
  File "<frozen importlib._bootstrap>", line 222, in _call_with_frames_removed
  File "C:\Users\nicos\Desktop\cronanbot\CronanBot\cogs\fidget.py", line 40
    await send_file(message.channel, FIDGET_SPINNERS,*, filename=None, content=message, tts=False)
                                                      ^
SyntaxError: invalid syntax

During handling of the above exception, another exception occurred:

Traceback (most recent call last):
  File "red.py", line 572, in load_cogs
    owner_cog._load_cog(extension)
  File "C:\Users\nicos\Desktop\cronanbot\CronanBot\cogs\owner.py", line 935, in _load_cog
    raise CogLoadError(*e.args)
cogs.owner.CogLoadError: ('invalid syntax', ('C:\\Users\\nicos\\Desktop\\cronanbot\\CronanBot\\cogs\\fidget.py', 40, 59, '        await send_file(message.channel, FIDGET_SPINNERS,*, filename=None, content=message, tts=False)\n'))
[17/07/2017 16:55] ERROR red on_command_error 371: Exception in command 'help'
Traceback (most recent call last):
  File "lib\discord\ext\commands\core.py", line 50, in wrapped
    ret = yield from coro(*args, **kwargs)
  File "lib\discord\ext\commands\bot.py", line 102, in _default_help_command
    pages = bot.formatter.format_help_for(ctx, bot)
  File "lib\discord\ext\commands\formatter.py", line 291, in format_help_for
    return self.format()
  File "lib\discord\ext\commands\formatter.py", line 336, in format
    data = sorted(self.filter_command_list(), key=category)
  File "lib\discord\ext\commands\formatter.py", line 255, in predicate
    return cmd.can_run(self.context) and self.context.bot.can_run(self.context)
  File "lib\discord\ext\commands\core.py", line 438, in can_run
    return all(predicate(context) for predicate in predicates)
  File "lib\discord\ext\commands\core.py", line 438, in <genexpr>
    return all(predicate(context) for predicate in predicates)
  File "C:\Users\nicos\Desktop\cronanbot\CronanBot\cogs\fidget.py", line 24, in is_not_spinning
    if ctx.author.id in spinners:
AttributeError: 'Context' object has no attribute 'author'
[17/07/2017 17:00] ERROR red load_cogs 575: HTTPSConnectionPool(host='api.imgur.com', port=443): Max retries exceeded with url: /3/credits (Caused by NewConnectionError('<urllib3.connection.VerifiedHTTPSConnection object at 0x000001C89A4F5C88>: Failed to establish a new connection: [Errno 11001] getaddrinfo failed',))
Traceback (most recent call last):
  File "lib\urllib3\connection.py", line 141, in _new_conn
    (self.host, self.port), self.timeout, **extra_kw)
  File "lib\urllib3\util\connection.py", line 60, in create_connection
    for res in socket.getaddrinfo(host, port, family, socket.SOCK_STREAM):
  File "C:\Users\nicos\AppData\Local\Programs\Python\Python35\lib\socket.py", line 732, in getaddrinfo
    for res in _socket.getaddrinfo(host, port, family, type, proto, flags):
socket.gaierror: [Errno 11001] getaddrinfo failed

During handling of the above exception, another exception occurred:

Traceback (most recent call last):
  File "lib\urllib3\connectionpool.py", line 600, in urlopen
    chunked=chunked)
  File "lib\urllib3\connectionpool.py", line 345, in _make_request
    self._validate_conn(conn)
  File "lib\urllib3\connectionpool.py", line 844, in _validate_conn
    conn.connect()
  File "lib\urllib3\connection.py", line 284, in connect
    conn = self._new_conn()
  File "lib\urllib3\connection.py", line 150, in _new_conn
    self, "Failed to establish a new connection: %s" % e)
urllib3.exceptions.NewConnectionError: <urllib3.connection.VerifiedHTTPSConnection object at 0x000001C89A4F5C88>: Failed to establish a new connection: [Errno 11001] getaddrinfo failed

During handling of the above exception, another exception occurred:

Traceback (most recent call last):
  File "lib\requests\adapters.py", line 440, in send
    timeout=timeout
  File "lib\urllib3\connectionpool.py", line 649, in urlopen
    _stacktrace=sys.exc_info()[2])
  File "lib\urllib3\util\retry.py", line 388, in increment
    raise MaxRetryError(_pool, url, error or ResponseError(cause))
urllib3.exceptions.MaxRetryError: HTTPSConnectionPool(host='api.imgur.com', port=443): Max retries exceeded with url: /3/credits (Caused by NewConnectionError('<urllib3.connection.VerifiedHTTPSConnection object at 0x000001C89A4F5C88>: Failed to establish a new connection: [Errno 11001] getaddrinfo failed',))

During handling of the above exception, another exception occurred:

Traceback (most recent call last):
  File "red.py", line 572, in load_cogs
    owner_cog._load_cog(extension)
  File "C:\Users\nicos\Desktop\cronanbot\CronanBot\cogs\owner.py", line 933, in _load_cog
    self.bot.load_extension(mod_obj.__name__)
  File "lib\discord\ext\commands\bot.py", line 738, in load_extension
    lib.setup(self)
  File "C:\Users\nicos\Desktop\cronanbot\CronanBot\cogs\image.py", line 168, in setup
    bot.add_cog(Image(bot))
  File "C:\Users\nicos\Desktop\cronanbot\CronanBot\cogs\image.py", line 22, in __init__
    self.imgur = ImgurClient(CLIENT_ID, CLIENT_SECRET)
  File "lib\imgurpython\client.py", line 85, in __init__
    self.credits = self.get_credits()
  File "lib\imgurpython\client.py", line 94, in get_credits
    return self.make_request('GET', 'credits', None, True)
  File "lib\imgurpython\client.py", line 131, in make_request
    response = method_to_call(url, headers=header, params=data, data=data)
  File "lib\requests\api.py", line 72, in get
    return request('get', url, params=params, **kwargs)
  File "lib\requests\api.py", line 58, in request
    return session.request(method=method, url=url, **kwargs)
  File "lib\requests\sessions.py", line 502, in request
    resp = self.send(prep, **send_kwargs)
  File "lib\requests\sessions.py", line 612, in send
    r = adapter.send(request, **kwargs)
  File "lib\requests\adapters.py", line 504, in send
    raise ConnectionError(e, request=request)
requests.exceptions.ConnectionError: HTTPSConnectionPool(host='api.imgur.com', port=443): Max retries exceeded with url: /3/credits (Caused by NewConnectionError('<urllib3.connection.VerifiedHTTPSConnection object at 0x000001C89A4F5C88>: Failed to establish a new connection: [Errno 11001] getaddrinfo failed',))
[17/07/2017 17:00] ERROR red <module> 636: Fatal exception, attempting graceful logout
Traceback (most recent call last):
  File "lib\aiohttp\connector.py", line 304, in connect
    yield from self._create_connection(req)
  File "lib\aiohttp\connector.py", line 578, in _create_connection
    transport, proto = yield from self._create_direct_connection(req)
  File "lib\aiohttp\connector.py", line 589, in _create_direct_connection
    hosts = yield from self._resolve_host(req.host, req.port)
  File "lib\aiohttp\connector.py", line 561, in _resolve_host
    self._resolver.resolve(host, port, family=self._family)
  File "lib\aiohttp\resolver.py", line 29, in resolve
    host, port, type=socket.SOCK_STREAM, family=family)
  File "C:\Users\nicos\AppData\Local\Programs\Python\Python35\lib\asyncio\futures.py", line 358, in __iter__
    yield self  # This tells Task to wait for completion.
  File "C:\Users\nicos\AppData\Local\Programs\Python\Python35\lib\asyncio\tasks.py", line 290, in _wakeup
    future.result()
  File "C:\Users\nicos\AppData\Local\Programs\Python\Python35\lib\asyncio\futures.py", line 274, in result
    raise self._exception
  File "C:\Users\nicos\AppData\Local\Programs\Python\Python35\lib\concurrent\futures\thread.py", line 55, in run
    result = self.fn(*self.args, **self.kwargs)
  File "C:\Users\nicos\AppData\Local\Programs\Python\Python35\lib\socket.py", line 732, in getaddrinfo
    for res in _socket.getaddrinfo(host, port, family, type, proto, flags):
socket.gaierror: [Errno 11001] getaddrinfo failed

The above exception was the direct cause of the following exception:

Traceback (most recent call last):
  File "red.py", line 616, in <module>
    loop.run_until_complete(main(bot))
  File "C:\Users\nicos\AppData\Local\Programs\Python\Python35\lib\asyncio\base_events.py", line 337, in run_until_complete
    return future.result()
  File "C:\Users\nicos\AppData\Local\Programs\Python\Python35\lib\asyncio\futures.py", line 274, in result
    raise self._exception
  File "C:\Users\nicos\AppData\Local\Programs\Python\Python35\lib\asyncio\tasks.py", line 241, in _step
    result = coro.throw(exc)
  File "red.py", line 601, in main
    bot=not bot.settings.self_bot)
  File "lib\discord\client.py", line 416, in login
    yield from getattr(self, '_login_' + str(n))(*args, **kwargs)
  File "lib\discord\client.py", line 346, in _login_1
    data = yield from self.http.static_login(token, bot=is_bot)
  File "lib\discord\http.py", line 258, in static_login
    data = yield from self.request(Route('GET', '/users/@me'))
  File "lib\discord\http.py", line 137, in request
    r = yield from self.session.request(method, url, **kwargs)
  File "lib\aiohttp\client.py", line 555, in __iter__
    resp = yield from self._coro
  File "lib\aiohttp\client.py", line 198, in _request
    conn = yield from self._connector.connect(req)
  File "lib\aiohttp\connector.py", line 314, in connect
    .format(key, exc.strerror)) from exc
aiohttp.errors.ClientOSError: [Errno 11001] Cannot connect to host discordapp.com:443 ssl:True [getaddrinfo failed]
[17/07/2017 17:06] ERROR red on_command_error 371: Exception in command 'spinner'
Traceback (most recent call last):
  File "lib\discord\ext\commands\core.py", line 50, in wrapped
    ret = yield from coro(*args, **kwargs)
  File "C:\Users\nicos\Desktop\cronanbot\CronanBot\cogs\fidget.py", line 36, in spinner
    author = ctx.message.author
AttributeError: 'str' object has no attribute 'message'
[17/07/2017 17:09] ERROR red on_command_error 371: Exception in command 'spinner'
Traceback (most recent call last):
  File "lib\discord\ext\commands\core.py", line 50, in wrapped
    ret = yield from coro(*args, **kwargs)
  File "C:\Users\nicos\Desktop\cronanbot\CronanBot\cogs\fidget.py", line 38, in spinner
    author = ctx.message.author
AttributeError: 'str' object has no attribute 'message'
[17/07/2017 17:12] ERROR red on_command_error 371: Exception in command 'spinner'
Traceback (most recent call last):
  File "lib\discord\ext\commands\core.py", line 50, in wrapped
    ret = yield from coro(*args, **kwargs)
  File "C:\Users\nicos\Desktop\cronanbot\CronanBot\cogs\fidget.py", line 38, in spinner
    author = ctx.message.author
AttributeError: 'str' object has no attribute 'message'
[17/07/2017 17:12] ERROR red on_command_error 371: Exception in command 'spinner'
Traceback (most recent call last):
  File "lib\discord\ext\commands\core.py", line 50, in wrapped
    ret = yield from coro(*args, **kwargs)
  File "C:\Users\nicos\Desktop\cronanbot\CronanBot\cogs\fidget.py", line 38, in spinner
    author = ctx.message.author
AttributeError: 'str' object has no attribute 'message'
[17/07/2017 17:27] ERROR red load_cogs 575: name 'General' is not defined
Traceback (most recent call last):
  File "red.py", line 572, in load_cogs
    owner_cog._load_cog(extension)
  File "C:\Users\nicos\Desktop\cronanbot\CronanBot\cogs\owner.py", line 933, in _load_cog
    self.bot.load_extension(mod_obj.__name__)
  File "lib\discord\ext\commands\bot.py", line 738, in load_extension
    lib.setup(self)
  File "C:\Users\nicos\Desktop\cronanbot\CronanBot\cogs\fidget.py", line 47, in setup
    n = General(bot)
NameError: name 'General' is not defined
[17/07/2017 17:35] ERROR red on_command_error 371: Exception in command 'spinner'
Traceback (most recent call last):
  File "lib\discord\ext\commands\core.py", line 50, in wrapped
    ret = yield from coro(*args, **kwargs)
  File "C:\Users\nicos\Desktop\cronanbot\CronanBot\cogs\general.py", line 335, in spinner
    if author.id in spinners:
NameError: name 'spinners' is not defined
[17/07/2017 17:36] ERROR red on_command_error 371: Exception in command 'spinner'
Traceback (most recent call last):
  File "lib\discord\ext\commands\core.py", line 50, in wrapped
    ret = yield from coro(*args, **kwargs)
  File "C:\Users\nicos\Desktop\cronanbot\CronanBot\cogs\general.py", line 342, in spinner
    await self.bot.say(author.mention + ", your spinner spun for " + duration + " seconds!")
TypeError: Can't convert 'int' object to str implicitly
[17/07/2017 17:41] ERROR red load_cogs 575: ('invalid syntax', ('C:\\Users\\nicos\\Desktop\\cronanbot\\CronanBot\\cogs\\general.py', 341, 23, '            awwait self.client.send_file(self.channel, choice(self.fidget), filename=None, content=None, tts=False)\n'))
Traceback (most recent call last):
  File "C:\Users\nicos\Desktop\cronanbot\CronanBot\cogs\owner.py", line 931, in _load_cog
    mod_obj = importlib.import_module(cogname)
  File "C:\Users\nicos\AppData\Local\Programs\Python\Python35\lib\importlib\__init__.py", line 126, in import_module
    return _bootstrap._gcd_import(name[level:], package, level)
  File "<frozen importlib._bootstrap>", line 986, in _gcd_import
  File "<frozen importlib._bootstrap>", line 969, in _find_and_load
  File "<frozen importlib._bootstrap>", line 958, in _find_and_load_unlocked
  File "<frozen importlib._bootstrap>", line 673, in _load_unlocked
  File "<frozen importlib._bootstrap_external>", line 658, in exec_module
  File "<frozen importlib._bootstrap_external>", line 764, in get_code
  File "<frozen importlib._bootstrap_external>", line 724, in source_to_code
  File "<frozen importlib._bootstrap>", line 222, in _call_with_frames_removed
  File "C:\Users\nicos\Desktop\cronanbot\CronanBot\cogs\general.py", line 341
    awwait self.client.send_file(self.channel, choice(self.fidget), filename=None, content=None, tts=False)
              ^
SyntaxError: invalid syntax

During handling of the above exception, another exception occurred:

Traceback (most recent call last):
  File "red.py", line 572, in load_cogs
    owner_cog._load_cog(extension)
  File "C:\Users\nicos\Desktop\cronanbot\CronanBot\cogs\owner.py", line 935, in _load_cog
    raise CogLoadError(*e.args)
cogs.owner.CogLoadError: ('invalid syntax', ('C:\\Users\\nicos\\Desktop\\cronanbot\\CronanBot\\cogs\\general.py', 341, 23, '            awwait self.client.send_file(self.channel, choice(self.fidget), filename=None, content=None, tts=False)\n'))
[17/07/2017 17:41] ERROR red load_cogs 575: HTTPSConnectionPool(host='api.imgur.com', port=443): Max retries exceeded with url: /3/credits (Caused by NewConnectionError('<urllib3.connection.VerifiedHTTPSConnection object at 0x0000022DA4CF6D30>: Failed to establish a new connection: [Errno 11001] getaddrinfo failed',))
Traceback (most recent call last):
  File "lib\urllib3\connection.py", line 141, in _new_conn
    (self.host, self.port), self.timeout, **extra_kw)
  File "lib\urllib3\util\connection.py", line 60, in create_connection
    for res in socket.getaddrinfo(host, port, family, socket.SOCK_STREAM):
  File "C:\Users\nicos\AppData\Local\Programs\Python\Python35\lib\socket.py", line 732, in getaddrinfo
    for res in _socket.getaddrinfo(host, port, family, type, proto, flags):
socket.gaierror: [Errno 11001] getaddrinfo failed

During handling of the above exception, another exception occurred:

Traceback (most recent call last):
  File "lib\urllib3\connectionpool.py", line 600, in urlopen
    chunked=chunked)
  File "lib\urllib3\connectionpool.py", line 345, in _make_request
    self._validate_conn(conn)
  File "lib\urllib3\connectionpool.py", line 844, in _validate_conn
    conn.connect()
  File "lib\urllib3\connection.py", line 284, in connect
    conn = self._new_conn()
  File "lib\urllib3\connection.py", line 150, in _new_conn
    self, "Failed to establish a new connection: %s" % e)
urllib3.exceptions.NewConnectionError: <urllib3.connection.VerifiedHTTPSConnection object at 0x0000022DA4CF6D30>: Failed to establish a new connection: [Errno 11001] getaddrinfo failed

During handling of the above exception, another exception occurred:

Traceback (most recent call last):
  File "lib\requests\adapters.py", line 440, in send
    timeout=timeout
  File "lib\urllib3\connectionpool.py", line 649, in urlopen
    _stacktrace=sys.exc_info()[2])
  File "lib\urllib3\util\retry.py", line 388, in increment
    raise MaxRetryError(_pool, url, error or ResponseError(cause))
urllib3.exceptions.MaxRetryError: HTTPSConnectionPool(host='api.imgur.com', port=443): Max retries exceeded with url: /3/credits (Caused by NewConnectionError('<urllib3.connection.VerifiedHTTPSConnection object at 0x0000022DA4CF6D30>: Failed to establish a new connection: [Errno 11001] getaddrinfo failed',))

During handling of the above exception, another exception occurred:

Traceback (most recent call last):
  File "red.py", line 572, in load_cogs
    owner_cog._load_cog(extension)
  File "C:\Users\nicos\Desktop\cronanbot\CronanBot\cogs\owner.py", line 933, in _load_cog
    self.bot.load_extension(mod_obj.__name__)
  File "lib\discord\ext\commands\bot.py", line 738, in load_extension
    lib.setup(self)
  File "C:\Users\nicos\Desktop\cronanbot\CronanBot\cogs\image.py", line 168, in setup
    bot.add_cog(Image(bot))
  File "C:\Users\nicos\Desktop\cronanbot\CronanBot\cogs\image.py", line 22, in __init__
    self.imgur = ImgurClient(CLIENT_ID, CLIENT_SECRET)
  File "lib\imgurpython\client.py", line 85, in __init__
    self.credits = self.get_credits()
  File "lib\imgurpython\client.py", line 94, in get_credits
    return self.make_request('GET', 'credits', None, True)
  File "lib\imgurpython\client.py", line 131, in make_request
    response = method_to_call(url, headers=header, params=data, data=data)
  File "lib\requests\api.py", line 72, in get
    return request('get', url, params=params, **kwargs)
  File "lib\requests\api.py", line 58, in request
    return session.request(method=method, url=url, **kwargs)
  File "lib\requests\sessions.py", line 502, in request
    resp = self.send(prep, **send_kwargs)
  File "lib\requests\sessions.py", line 612, in send
    r = adapter.send(request, **kwargs)
  File "lib\requests\adapters.py", line 504, in send
    raise ConnectionError(e, request=request)
requests.exceptions.ConnectionError: HTTPSConnectionPool(host='api.imgur.com', port=443): Max retries exceeded with url: /3/credits (Caused by NewConnectionError('<urllib3.connection.VerifiedHTTPSConnection object at 0x0000022DA4CF6D30>: Failed to establish a new connection: [Errno 11001] getaddrinfo failed',))
[17/07/2017 17:41] ERROR red <module> 636: Fatal exception, attempting graceful logout
Traceback (most recent call last):
  File "lib\aiohttp\connector.py", line 304, in connect
    yield from self._create_connection(req)
  File "lib\aiohttp\connector.py", line 578, in _create_connection
    transport, proto = yield from self._create_direct_connection(req)
  File "lib\aiohttp\connector.py", line 589, in _create_direct_connection
    hosts = yield from self._resolve_host(req.host, req.port)
  File "lib\aiohttp\connector.py", line 561, in _resolve_host
    self._resolver.resolve(host, port, family=self._family)
  File "lib\aiohttp\resolver.py", line 29, in resolve
    host, port, type=socket.SOCK_STREAM, family=family)
  File "C:\Users\nicos\AppData\Local\Programs\Python\Python35\lib\asyncio\futures.py", line 358, in __iter__
    yield self  # This tells Task to wait for completion.
  File "C:\Users\nicos\AppData\Local\Programs\Python\Python35\lib\asyncio\tasks.py", line 290, in _wakeup
    future.result()
  File "C:\Users\nicos\AppData\Local\Programs\Python\Python35\lib\asyncio\futures.py", line 274, in result
    raise self._exception
  File "C:\Users\nicos\AppData\Local\Programs\Python\Python35\lib\concurrent\futures\thread.py", line 55, in run
    result = self.fn(*self.args, **self.kwargs)
  File "C:\Users\nicos\AppData\Local\Programs\Python\Python35\lib\socket.py", line 732, in getaddrinfo
    for res in _socket.getaddrinfo(host, port, family, type, proto, flags):
socket.gaierror: [Errno 11001] getaddrinfo failed

The above exception was the direct cause of the following exception:

Traceback (most recent call last):
  File "red.py", line 616, in <module>
    loop.run_until_complete(main(bot))
  File "C:\Users\nicos\AppData\Local\Programs\Python\Python35\lib\asyncio\base_events.py", line 337, in run_until_complete
    return future.result()
  File "C:\Users\nicos\AppData\Local\Programs\Python\Python35\lib\asyncio\futures.py", line 274, in result
    raise self._exception
  File "C:\Users\nicos\AppData\Local\Programs\Python\Python35\lib\asyncio\tasks.py", line 241, in _step
    result = coro.throw(exc)
  File "red.py", line 601, in main
    bot=not bot.settings.self_bot)
  File "lib\discord\client.py", line 416, in login
    yield from getattr(self, '_login_' + str(n))(*args, **kwargs)
  File "lib\discord\client.py", line 346, in _login_1
    data = yield from self.http.static_login(token, bot=is_bot)
  File "lib\discord\http.py", line 258, in static_login
    data = yield from self.request(Route('GET', '/users/@me'))
  File "lib\discord\http.py", line 137, in request
    r = yield from self.session.request(method, url, **kwargs)
  File "lib\aiohttp\client.py", line 555, in __iter__
    resp = yield from self._coro
  File "lib\aiohttp\client.py", line 198, in _request
    conn = yield from self._connector.connect(req)
  File "lib\aiohttp\connector.py", line 314, in connect
    .format(key, exc.strerror)) from exc
aiohttp.errors.ClientOSError: [Errno 11001] Cannot connect to host discordapp.com:443 ssl:True [getaddrinfo failed]
[17/07/2017 17:45] ERROR red load_cogs 575: ('invalid syntax', ('C:\\Users\\nicos\\Desktop\\cronanbot\\CronanBot\\cogs\\general.py', 341, 23, '            awwait self.client.send_file(self.channel, choice(self.fidget), filename=None, content=None, tts=False)\n'))
Traceback (most recent call last):
  File "C:\Users\nicos\Desktop\cronanbot\CronanBot\cogs\owner.py", line 931, in _load_cog
    mod_obj = importlib.import_module(cogname)
  File "C:\Users\nicos\AppData\Local\Programs\Python\Python35\lib\importlib\__init__.py", line 126, in import_module
    return _bootstrap._gcd_import(name[level:], package, level)
  File "<frozen importlib._bootstrap>", line 986, in _gcd_import
  File "<frozen importlib._bootstrap>", line 969, in _find_and_load
  File "<frozen importlib._bootstrap>", line 958, in _find_and_load_unlocked
  File "<frozen importlib._bootstrap>", line 673, in _load_unlocked
  File "<frozen importlib._bootstrap_external>", line 658, in exec_module
  File "<frozen importlib._bootstrap_external>", line 764, in get_code
  File "<frozen importlib._bootstrap_external>", line 724, in source_to_code
  File "<frozen importlib._bootstrap>", line 222, in _call_with_frames_removed
  File "C:\Users\nicos\Desktop\cronanbot\CronanBot\cogs\general.py", line 341
    awwait self.client.send_file(self.channel, choice(self.fidget), filename=None, content=None, tts=False)
              ^
SyntaxError: invalid syntax

During handling of the above exception, another exception occurred:

Traceback (most recent call last):
  File "red.py", line 572, in load_cogs
    owner_cog._load_cog(extension)
  File "C:\Users\nicos\Desktop\cronanbot\CronanBot\cogs\owner.py", line 935, in _load_cog
    raise CogLoadError(*e.args)
cogs.owner.CogLoadError: ('invalid syntax', ('C:\\Users\\nicos\\Desktop\\cronanbot\\CronanBot\\cogs\\general.py', 341, 23, '            awwait self.client.send_file(self.channel, choice(self.fidget), filename=None, content=None, tts=False)\n'))
[17/07/2017 17:46] ERROR red load_cogs 575: ('invalid syntax', ('C:\\Users\\nicos\\Desktop\\cronanbot\\CronanBot\\cogs\\general.py', 341, 23, '            awwait self.send_file(self.channel, choice(self.fidget), filename=None, content=None, tts=False)\n'))
Traceback (most recent call last):
  File "C:\Users\nicos\Desktop\cronanbot\CronanBot\cogs\owner.py", line 931, in _load_cog
    mod_obj = importlib.import_module(cogname)
  File "C:\Users\nicos\AppData\Local\Programs\Python\Python35\lib\importlib\__init__.py", line 126, in import_module
    return _bootstrap._gcd_import(name[level:], package, level)
  File "<frozen importlib._bootstrap>", line 986, in _gcd_import
  File "<frozen importlib._bootstrap>", line 969, in _find_and_load
  File "<frozen importlib._bootstrap>", line 958, in _find_and_load_unlocked
  File "<frozen importlib._bootstrap>", line 673, in _load_unlocked
  File "<frozen importlib._bootstrap_external>", line 658, in exec_module
  File "<frozen importlib._bootstrap_external>", line 764, in get_code
  File "<frozen importlib._bootstrap_external>", line 724, in source_to_code
  File "<frozen importlib._bootstrap>", line 222, in _call_with_frames_removed
  File "C:\Users\nicos\Desktop\cronanbot\CronanBot\cogs\general.py", line 341
    awwait self.send_file(self.channel, choice(self.fidget), filename=None, content=None, tts=False)
              ^
SyntaxError: invalid syntax

During handling of the above exception, another exception occurred:

Traceback (most recent call last):
  File "red.py", line 572, in load_cogs
    owner_cog._load_cog(extension)
  File "C:\Users\nicos\Desktop\cronanbot\CronanBot\cogs\owner.py", line 935, in _load_cog
    raise CogLoadError(*e.args)
cogs.owner.CogLoadError: ('invalid syntax', ('C:\\Users\\nicos\\Desktop\\cronanbot\\CronanBot\\cogs\\general.py', 341, 23, '            awwait self.send_file(self.channel, choice(self.fidget), filename=None, content=None, tts=False)\n'))
[17/07/2017 17:47] ERROR red <module> 636: Fatal exception, attempting graceful logout
Traceback (most recent call last):
  File "lib\aiohttp\connector.py", line 601, in _create_direct_connection
    local_addr=self._local_addr)
  File "C:\Users\nicos\AppData\Local\Programs\Python\Python35\lib\asyncio\base_events.py", line 645, in create_connection
    raise exceptions[0]
  File "C:\Users\nicos\AppData\Local\Programs\Python\Python35\lib\asyncio\base_events.py", line 632, in create_connection
    yield from self.sock_connect(sock, address)
  File "C:\Users\nicos\AppData\Local\Programs\Python\Python35\lib\asyncio\futures.py", line 358, in __iter__
    yield self  # This tells Task to wait for completion.
  File "C:\Users\nicos\AppData\Local\Programs\Python\Python35\lib\asyncio\tasks.py", line 290, in _wakeup
    future.result()
  File "C:\Users\nicos\AppData\Local\Programs\Python\Python35\lib\asyncio\futures.py", line 274, in result
    raise self._exception
  File "C:\Users\nicos\AppData\Local\Programs\Python\Python35\lib\asyncio\selector_events.py", line 436, in _sock_connect_cb
    raise OSError(err, 'Connect call failed %s' % (address,))
OSError: [Errno 10065] Connect call failed ('104.16.59.5', 443)

The above exception was the direct cause of the following exception:

Traceback (most recent call last):
  File "lib\aiohttp\connector.py", line 304, in connect
    yield from self._create_connection(req)
  File "lib\aiohttp\connector.py", line 578, in _create_connection
    transport, proto = yield from self._create_direct_connection(req)
  File "lib\aiohttp\connector.py", line 624, in _create_direct_connection
    (req.host, req.port, exc.strerror)) from exc
aiohttp.errors.ClientOSError: [Errno 10065] Can not connect to discordapp.com:443 [Connect call failed ('104.16.59.5', 443)]

The above exception was the direct cause of the following exception:

Traceback (most recent call last):
  File "red.py", line 616, in <module>
    loop.run_until_complete(main(bot))
  File "C:\Users\nicos\AppData\Local\Programs\Python\Python35\lib\asyncio\base_events.py", line 337, in run_until_complete
    return future.result()
  File "C:\Users\nicos\AppData\Local\Programs\Python\Python35\lib\asyncio\futures.py", line 274, in result
    raise self._exception
  File "C:\Users\nicos\AppData\Local\Programs\Python\Python35\lib\asyncio\tasks.py", line 241, in _step
    result = coro.throw(exc)
  File "red.py", line 605, in main
    yield from bot.connect()
  File "lib\discord\client.py", line 452, in connect
    self.ws = yield from DiscordWebSocket.from_client(self, resume=resume)
  File "lib\discord\gateway.py", line 203, in from_client
    gateway = yield from client.http.get_gateway()
  File "lib\discord\http.py", line 633, in get_gateway
    data = yield from self.request(Route('GET', '/gateway'))
  File "lib\discord\http.py", line 137, in request
    r = yield from self.session.request(method, url, **kwargs)
  File "lib\aiohttp\client.py", line 555, in __iter__
    resp = yield from self._coro
  File "lib\aiohttp\client.py", line 198, in _request
    conn = yield from self._connector.connect(req)
  File "lib\aiohttp\connector.py", line 314, in connect
    .format(key, exc.strerror)) from exc
aiohttp.errors.ClientOSError: [Errno 10065] Cannot connect to host discordapp.com:443 ssl:True [Can not connect to discordapp.com:443 [Connect call failed ('104.16.59.5', 443)]]
[17/07/2017 17:52] ERROR red load_cogs 575: ('invalid syntax', ('C:\\Users\\nicos\\Desktop\\cronanbot\\CronanBot\\cogs\\general.py', 341, 25, '            awwait client.send_file(self.channel, choice(self.fidget), filename=None, content=None, tts=False)\n'))
Traceback (most recent call last):
  File "C:\Users\nicos\Desktop\cronanbot\CronanBot\cogs\owner.py", line 931, in _load_cog
    mod_obj = importlib.import_module(cogname)
  File "C:\Users\nicos\AppData\Local\Programs\Python\Python35\lib\importlib\__init__.py", line 126, in import_module
    return _bootstrap._gcd_import(name[level:], package, level)
  File "<frozen importlib._bootstrap>", line 986, in _gcd_import
  File "<frozen importlib._bootstrap>", line 969, in _find_and_load
  File "<frozen importlib._bootstrap>", line 958, in _find_and_load_unlocked
  File "<frozen importlib._bootstrap>", line 673, in _load_unlocked
  File "<frozen importlib._bootstrap_external>", line 658, in exec_module
  File "<frozen importlib._bootstrap_external>", line 764, in get_code
  File "<frozen importlib._bootstrap_external>", line 724, in source_to_code
  File "<frozen importlib._bootstrap>", line 222, in _call_with_frames_removed
  File "C:\Users\nicos\Desktop\cronanbot\CronanBot\cogs\general.py", line 341
    awwait client.send_file(self.channel, choice(self.fidget), filename=None, content=None, tts=False)
                ^
SyntaxError: invalid syntax

During handling of the above exception, another exception occurred:

Traceback (most recent call last):
  File "red.py", line 572, in load_cogs
    owner_cog._load_cog(extension)
  File "C:\Users\nicos\Desktop\cronanbot\CronanBot\cogs\owner.py", line 935, in _load_cog
    raise CogLoadError(*e.args)
cogs.owner.CogLoadError: ('invalid syntax', ('C:\\Users\\nicos\\Desktop\\cronanbot\\CronanBot\\cogs\\general.py', 341, 25, '            awwait client.send_file(self.channel, choice(self.fidget), filename=None, content=None, tts=False)\n'))
[17/07/2017 17:54] ERROR red on_command_error 371: Exception in command 'spinner'
Traceback (most recent call last):
  File "lib\discord\ext\commands\core.py", line 50, in wrapped
    ret = yield from coro(*args, **kwargs)
  File "C:\Users\nicos\Desktop\cronanbot\CronanBot\cogs\general.py", line 341, in spinner
    await client.send_file(self.channel, choice(self.fidget), filename=None, content=None, tts=False)
NameError: name 'client' is not defined
[17/07/2017 17:55] ERROR red on_command_error 371: Exception in command 'spinner'
Traceback (most recent call last):
  File "lib\discord\ext\commands\core.py", line 50, in wrapped
    ret = yield from coro(*args, **kwargs)
  File "C:\Users\nicos\Desktop\cronanbot\CronanBot\cogs\general.py", line 341, in spinner
    await self.send_file(self.channel, choice(self.fidget), filename=None, content=None, tts=False)
AttributeError: 'General' object has no attribute 'send_file'
[17/07/2017 17:59] ERROR red on_command_error 371: Exception in command 'spinner'
Traceback (most recent call last):
  File "lib\discord\ext\commands\core.py", line 50, in wrapped
    ret = yield from coro(*args, **kwargs)
  File "C:\Users\nicos\Desktop\cronanbot\CronanBot\cogs\general.py", line 341, in spinner
    await self.bot.upload(choice(self.fidget))
  File "lib\discord\ext\commands\bot.py", line 309, in _augmented_msg
    msg = yield from coro
  File "lib\discord\client.py", line 1226, in send_file
    with open(fp, 'rb') as f:
OSError: [Errno 22] Invalid argument: 'http://media.boingboing.net/wp-content/uploads/2017/02/good-spin.gif'
[17/07/2017 18:01] ERROR red on_command_error 371: Exception in command 'spinner'
Traceback (most recent call last):
  File "lib\discord\ext\commands\core.py", line 50, in wrapped
    ret = yield from coro(*args, **kwargs)
  File "C:\Users\nicos\Desktop\cronanbot\CronanBot\cogs\general.py", line 341, in spinner
    await self.bot.upload(self.channel, choice(self.fidget))
AttributeError: 'General' object has no attribute 'channel'
[17/07/2017 18:13] ERROR red on_command_error 371: Exception in command 'spinner'
Traceback (most recent call last):
  File "lib\discord\ext\commands\core.py", line 50, in wrapped
    ret = yield from coro(*args, **kwargs)
  File "C:\Users\nicos\Desktop\cronanbot\CronanBot\cogs\general.py", line 337, in spinner
    embed.set_image(chosenspinner)
TypeError: set_image() takes 1 positional argument but 2 were given
[17/07/2017 18:20] ERROR red on_command_error 371: Exception in command 'spinner'
Traceback (most recent call last):
  File "lib\discord\ext\commands\core.py", line 50, in wrapped
    ret = yield from coro(*args, **kwargs)
  File "C:\Users\nicos\Desktop\cronanbot\CronanBot\cogs\general.py", line 337, in spinner
    embed.set_image(chosenspinner)
TypeError: set_image() takes 1 positional argument but 2 were given
[17/07/2017 18:22] ERROR red on_command_error 371: Exception in command 'spinner'
Traceback (most recent call last):
  File "lib\discord\ext\commands\core.py", line 50, in wrapped
    ret = yield from coro(*args, **kwargs)
  File "C:\Users\nicos\Desktop\cronanbot\CronanBot\cogs\general.py", line 336, in spinner
    embed.set_image(choice(self.fidget))
TypeError: set_image() takes 1 positional argument but 2 were given
[17/07/2017 18:23] ERROR red on_command_error 371: Exception in command 'spinner'
Traceback (most recent call last):
  File "lib\discord\ext\commands\core.py", line 50, in wrapped
    ret = yield from coro(*args, **kwargs)
  File "C:\Users\nicos\Desktop\cronanbot\CronanBot\cogs\general.py", line 338, in spinner
    embed.set_image(chosenspinner)
TypeError: set_image() takes 1 positional argument but 2 were given
[17/07/2017 18:33] ERROR red on_command_error 371: Exception in command 'spinner'
Traceback (most recent call last):
  File "lib\discord\ext\commands\core.py", line 50, in wrapped
    ret = yield from coro(*args, **kwargs)
  File "C:\Users\nicos\Desktop\cronanbot\CronanBot\cogs\general.py", line 338, in spinner
    embed.set_image(chosenspinner)
TypeError: set_image() takes 1 positional argument but 2 were given
[17/07/2017 18:35] ERROR red on_command_error 371: Exception in command 'spinner'
Traceback (most recent call last):
  File "lib\discord\ext\commands\core.py", line 50, in wrapped
    ret = yield from coro(*args, **kwargs)
  File "C:\Users\nicos\Desktop\cronanbot\CronanBot\cogs\general.py", line 335, in spinner
    chosenspinner = str(chosenspinner)
UnboundLocalError: local variable 'chosenspinner' referenced before assignment
[17/07/2017 18:35] ERROR red on_command_error 371: Exception in command 'spinner'
Traceback (most recent call last):
  File "lib\discord\ext\commands\core.py", line 50, in wrapped
    ret = yield from coro(*args, **kwargs)
  File "C:\Users\nicos\Desktop\cronanbot\CronanBot\cogs\general.py", line 336, in spinner
    embed.set_image(choice(fidget))
TypeError: set_image() takes 1 positional argument but 2 were given
[17/07/2017 18:44] ERROR red on_command_error 371: Exception in command 'spinner'
Traceback (most recent call last):
  File "lib\discord\ext\commands\core.py", line 50, in wrapped
    ret = yield from coro(*args, **kwargs)
  File "C:\Users\nicos\Desktop\cronanbot\CronanBot\cogs\general.py", line 342, in spinner
    await utils.helpers.send_image(ctx, spinner, message=message)
NameError: name 'utils' is not defined
[17/07/2017 18:47] ERROR red load_cogs 575: No module named 'utils'
Traceback (most recent call last):
  File "red.py", line 572, in load_cogs
    owner_cog._load_cog(extension)
  File "C:\Users\nicos\Desktop\cronanbot\CronanBot\cogs\owner.py", line 931, in _load_cog
    mod_obj = importlib.import_module(cogname)
  File "C:\Users\nicos\AppData\Local\Programs\Python\Python35\lib\importlib\__init__.py", line 126, in import_module
    return _bootstrap._gcd_import(name[level:], package, level)
  File "<frozen importlib._bootstrap>", line 986, in _gcd_import
  File "<frozen importlib._bootstrap>", line 969, in _find_and_load
  File "<frozen importlib._bootstrap>", line 958, in _find_and_load_unlocked
  File "<frozen importlib._bootstrap>", line 673, in _load_unlocked
  File "<frozen importlib._bootstrap_external>", line 662, in exec_module
  File "<frozen importlib._bootstrap>", line 222, in _call_with_frames_removed
  File "C:\Users\nicos\Desktop\cronanbot\CronanBot\cogs\general.py", line 12, in <module>
    import utils.helpers
ImportError: No module named 'utils'
[17/07/2017 18:49] ERROR red load_cogs 575: No module named 'utils'
Traceback (most recent call last):
  File "red.py", line 572, in load_cogs
    owner_cog._load_cog(extension)
  File "C:\Users\nicos\Desktop\cronanbot\CronanBot\cogs\owner.py", line 931, in _load_cog
    mod_obj = importlib.import_module(cogname)
  File "C:\Users\nicos\AppData\Local\Programs\Python\Python35\lib\importlib\__init__.py", line 126, in import_module
    return _bootstrap._gcd_import(name[level:], package, level)
  File "<frozen importlib._bootstrap>", line 986, in _gcd_import
  File "<frozen importlib._bootstrap>", line 969, in _find_and_load
  File "<frozen importlib._bootstrap>", line 958, in _find_and_load_unlocked
  File "<frozen importlib._bootstrap>", line 673, in _load_unlocked
  File "<frozen importlib._bootstrap_external>", line 662, in exec_module
  File "<frozen importlib._bootstrap>", line 222, in _call_with_frames_removed
  File "C:\Users\nicos\Desktop\cronanbot\CronanBot\cogs\general.py", line 12, in <module>
    import utils.helpers
ImportError: No module named 'utils'
[17/07/2017 18:51] ERROR red load_cogs 575: No module named 'utils'
Traceback (most recent call last):
  File "red.py", line 572, in load_cogs
    owner_cog._load_cog(extension)
  File "C:\Users\nicos\Desktop\cronanbot\CronanBot\cogs\owner.py", line 931, in _load_cog
    mod_obj = importlib.import_module(cogname)
  File "C:\Users\nicos\AppData\Local\Programs\Python\Python35\lib\importlib\__init__.py", line 126, in import_module
    return _bootstrap._gcd_import(name[level:], package, level)
  File "<frozen importlib._bootstrap>", line 986, in _gcd_import
  File "<frozen importlib._bootstrap>", line 969, in _find_and_load
  File "<frozen importlib._bootstrap>", line 958, in _find_and_load_unlocked
  File "<frozen importlib._bootstrap>", line 673, in _load_unlocked
  File "<frozen importlib._bootstrap_external>", line 662, in exec_module
  File "<frozen importlib._bootstrap>", line 222, in _call_with_frames_removed
  File "C:\Users\nicos\Desktop\cronanbot\CronanBot\cogs\general.py", line 12, in <module>
    from utils.helpers import send_image
ImportError: No module named 'utils'
[17/07/2017 18:51] ERROR red load_cogs 575: No module named 'utils'
Traceback (most recent call last):
  File "red.py", line 572, in load_cogs
    owner_cog._load_cog(extension)
  File "C:\Users\nicos\Desktop\cronanbot\CronanBot\cogs\owner.py", line 931, in _load_cog
    mod_obj = importlib.import_module(cogname)
  File "C:\Users\nicos\AppData\Local\Programs\Python\Python35\lib\importlib\__init__.py", line 126, in import_module
    return _bootstrap._gcd_import(name[level:], package, level)
  File "<frozen importlib._bootstrap>", line 986, in _gcd_import
  File "<frozen importlib._bootstrap>", line 969, in _find_and_load
  File "<frozen importlib._bootstrap>", line 958, in _find_and_load_unlocked
  File "<frozen importlib._bootstrap>", line 673, in _load_unlocked
  File "<frozen importlib._bootstrap_external>", line 662, in exec_module
  File "<frozen importlib._bootstrap>", line 222, in _call_with_frames_removed
  File "C:\Users\nicos\Desktop\cronanbot\CronanBot\cogs\general.py", line 12, in <module>
    from utils.helpers import send_image
ImportError: No module named 'utils'
[17/07/2017 18:58] ERROR red on_command_error 371: Exception in command 'spinner'
Traceback (most recent call last):
  File "lib\discord\ext\commands\core.py", line 50, in wrapped
    ret = yield from coro(*args, **kwargs)
  File "C:\Users\nicos\Desktop\cronanbot\CronanBot\cogs\general.py", line 338, in spinner
    chosenspinner = choice(spin.fidget)
NameError: name 'spin' is not defined
[17/07/2017 19:00] ERROR red on_command_error 371: Exception in command 'spinner'
Traceback (most recent call last):
  File "lib\discord\ext\commands\core.py", line 50, in wrapped
    ret = yield from coro(*args, **kwargs)
  File "C:\Users\nicos\Desktop\cronanbot\CronanBot\cogs\general.py", line 338, in spinner
    chosenspinner = choice(fidget)
NameError: name 'fidget' is not defined
[17/07/2017 19:02] ERROR red on_command_error 371: Exception in command 'spinner'
Traceback (most recent call last):
  File "lib\discord\ext\commands\core.py", line 50, in wrapped
    ret = yield from coro(*args, **kwargs)
  File "C:\Users\nicos\Desktop\cronanbot\CronanBot\cogs\general.py", line 343, in spinner
    chosenspinner = choice(Spin.fidget)
AttributeError: type object 'Spin' has no attribute 'fidget'
[17/07/2017 19:09] ERROR red on_command_error 371: Exception in command 'spinner'
Traceback (most recent call last):
  File "lib\discord\ext\commands\core.py", line 50, in wrapped
    ret = yield from coro(*args, **kwargs)
  File "C:\Users\nicos\Desktop\cronanbot\CronanBot\cogs\general.py", line 343, in spinner
    chosenspinner = choice(Spin.fidget)
AttributeError: type object 'Spin' has no attribute 'fidget'
[17/07/2017 19:16] ERROR red on_command_error 371: Exception in command 'spinner'
Traceback (most recent call last):
  File "lib\discord\ext\commands\core.py", line 50, in wrapped
    ret = yield from coro(*args, **kwargs)
  File "C:\Users\nicos\Desktop\cronanbot\CronanBot\cogs\general.py", line 343, in spinner
    chosenspinner = choice(Spin.fidget)
AttributeError: type object 'Spin' has no attribute 'fidget'
[17/07/2017 19:17] ERROR red on_command_error 371: Exception in command 'spinner'
Traceback (most recent call last):
  File "lib\discord\ext\commands\core.py", line 50, in wrapped
    ret = yield from coro(*args, **kwargs)
  File "C:\Users\nicos\Desktop\cronanbot\CronanBot\cogs\general.py", line 343, in spinner
    chosenspinner = choice(self.fidget)
AttributeError: 'General' object has no attribute 'fidget'
[17/07/2017 19:25] ERROR red on_command_error 371: Exception in command 'spinner'
Traceback (most recent call last):
  File "lib\discord\ext\commands\core.py", line 50, in wrapped
    ret = yield from coro(*args, **kwargs)
  File "C:\Users\nicos\Desktop\cronanbot\CronanBot\cogs\general.py", line 342, in spinner
    Spin.fid()
TypeError: fid() missing 1 required positional argument: 'self'
[17/07/2017 19:26] ERROR red on_command_error 371: Exception in command 'spinner'
Traceback (most recent call last):
  File "lib\discord\ext\commands\core.py", line 50, in wrapped
    ret = yield from coro(*args, **kwargs)
  File "C:\Users\nicos\Desktop\cronanbot\CronanBot\cogs\general.py", line 347, in spinner
    embed.set_image(chosenspinner)
TypeError: set_image() takes 1 positional argument but 2 were given
[17/07/2017 19:35] ERROR red on_command_error 371: Exception in command 'spinner'
Traceback (most recent call last):
  File "lib\discord\ext\commands\core.py", line 50, in wrapped
    ret = yield from coro(*args, **kwargs)
  File "C:\Users\nicos\Desktop\cronanbot\CronanBot\cogs\general.py", line 346, in spinner
    chosenspinner = choice(General.fidget)
AttributeError: type object 'General' has no attribute 'fidget'
[17/07/2017 19:37] ERROR red on_command_error 371: Exception in command 'spinner'
Traceback (most recent call last):
  File "lib\discord\ext\commands\core.py", line 50, in wrapped
    ret = yield from coro(*args, **kwargs)
  File "C:\Users\nicos\Desktop\cronanbot\CronanBot\cogs\general.py", line 347, in spinner
    chosenspinner = choice(self.fig)
AttributeError: 'General' object has no attribute 'fig'
[17/07/2017 19:41] ERROR red on_command_error 371: Exception in command 'spinner'
Traceback (most recent call last):
  File "lib\discord\ext\commands\core.py", line 50, in wrapped
    ret = yield from coro(*args, **kwargs)
  File "C:\Users\nicos\Desktop\cronanbot\CronanBot\cogs\general.py", line 348, in spinner
    chosenspinner = choice(self.fig)
AttributeError: 'General' object has no attribute 'fig'
[17/07/2017 19:45] ERROR red on_command_error 371: Exception in command 'spinner'
Traceback (most recent call last):
  File "lib\discord\ext\commands\core.py", line 50, in wrapped
    ret = yield from coro(*args, **kwargs)
  File "C:\Users\nicos\Desktop\cronanbot\CronanBot\cogs\general.py", line 348, in spinner
    chosenspinner = choice(self.fig)
AttributeError: 'General' object has no attribute 'fig'
[17/07/2017 19:51] ERROR red load_cogs 575: ('invalid syntax', ('C:\\Users\\nicos\\Desktop\\cronanbot\\CronanBot\\cogs\\general.py', 63, 5, '    `   fidg.spi = fig\n'))
Traceback (most recent call last):
  File "C:\Users\nicos\Desktop\cronanbot\CronanBot\cogs\owner.py", line 931, in _load_cog
    mod_obj = importlib.import_module(cogname)
  File "C:\Users\nicos\AppData\Local\Programs\Python\Python35\lib\importlib\__init__.py", line 126, in import_module
    return _bootstrap._gcd_import(name[level:], package, level)
  File "<frozen importlib._bootstrap>", line 986, in _gcd_import
  File "<frozen importlib._bootstrap>", line 969, in _find_and_load
  File "<frozen importlib._bootstrap>", line 958, in _find_and_load_unlocked
  File "<frozen importlib._bootstrap>", line 673, in _load_unlocked
  File "<frozen importlib._bootstrap_external>", line 658, in exec_module
  File "<frozen importlib._bootstrap_external>", line 764, in get_code
  File "<frozen importlib._bootstrap_external>", line 724, in source_to_code
  File "<frozen importlib._bootstrap>", line 222, in _call_with_frames_removed
  File "C:\Users\nicos\Desktop\cronanbot\CronanBot\cogs\general.py", line 63
    `   fidg.spi = fig
    ^
SyntaxError: invalid syntax

During handling of the above exception, another exception occurred:

Traceback (most recent call last):
  File "red.py", line 572, in load_cogs
    owner_cog._load_cog(extension)
  File "C:\Users\nicos\Desktop\cronanbot\CronanBot\cogs\owner.py", line 935, in _load_cog
    raise CogLoadError(*e.args)
cogs.owner.CogLoadError: ('invalid syntax', ('C:\\Users\\nicos\\Desktop\\cronanbot\\CronanBot\\cogs\\general.py', 63, 5, '    `   fidg.spi = fig\n'))
[17/07/2017 19:53] ERROR red on_command_error 371: Exception in command 'spinner'
Traceback (most recent call last):
  File "lib\discord\ext\commands\core.py", line 50, in wrapped
    ret = yield from coro(*args, **kwargs)
  File "C:\Users\nicos\Desktop\cronanbot\CronanBot\cogs\general.py", line 347, in spinner
    chosenspinner = choice(fidg.spi)
NameError: name 'fidg' is not defined
[17/07/2017 19:55] ERROR red on_command_error 371: Exception in command 'spinner'
Traceback (most recent call last):
  File "lib\discord\ext\commands\core.py", line 50, in wrapped
    ret = yield from coro(*args, **kwargs)
  File "C:\Users\nicos\Desktop\cronanbot\CronanBot\cogs\general.py", line 346, in spinner
    fidg()
NameError: name 'fidg' is not defined
[17/07/2017 20:16] ERROR red load_cogs 575: ('unindent does not match any outer indentation level', ('C:\\Users\\nicos\\Desktop\\cronanbot\\CronanBot\\cogs\\general.py', 333, 95, '       fidget = ["http://1.media.dorkly.cvcdn.com/98/93/8faa22b41bcbe455830907387af3a44b.gif",\n'))
Traceback (most recent call last):
  File "C:\Users\nicos\Desktop\cronanbot\CronanBot\cogs\owner.py", line 931, in _load_cog
    mod_obj = importlib.import_module(cogname)
  File "C:\Users\nicos\AppData\Local\Programs\Python\Python35\lib\importlib\__init__.py", line 126, in import_module
    return _bootstrap._gcd_import(name[level:], package, level)
  File "<frozen importlib._bootstrap>", line 986, in _gcd_import
  File "<frozen importlib._bootstrap>", line 969, in _find_and_load
  File "<frozen importlib._bootstrap>", line 958, in _find_and_load_unlocked
  File "<frozen importlib._bootstrap>", line 673, in _load_unlocked
  File "<frozen importlib._bootstrap_external>", line 658, in exec_module
  File "<frozen importlib._bootstrap_external>", line 764, in get_code
  File "<frozen importlib._bootstrap_external>", line 724, in source_to_code
  File "<frozen importlib._bootstrap>", line 222, in _call_with_frames_removed
  File "C:\Users\nicos\Desktop\cronanbot\CronanBot\cogs\general.py", line 333
    fidget = ["http://1.media.dorkly.cvcdn.com/98/93/8faa22b41bcbe455830907387af3a44b.gif",
                                                                                          ^
IndentationError: unindent does not match any outer indentation level

During handling of the above exception, another exception occurred:

Traceback (most recent call last):
  File "red.py", line 572, in load_cogs
    owner_cog._load_cog(extension)
  File "C:\Users\nicos\Desktop\cronanbot\CronanBot\cogs\owner.py", line 935, in _load_cog
    raise CogLoadError(*e.args)
cogs.owner.CogLoadError: ('unindent does not match any outer indentation level', ('C:\\Users\\nicos\\Desktop\\cronanbot\\CronanBot\\cogs\\general.py', 333, 95, '       fidget = ["http://1.media.dorkly.cvcdn.com/98/93/8faa22b41bcbe455830907387af3a44b.gif",\n'))
[17/07/2017 20:17] ERROR red load_cogs 575: ('unindent does not match any outer indentation level', ('C:\\Users\\nicos\\Desktop\\cronanbot\\CronanBot\\cogs\\general.py', 333, 95, '       fidget = ["http://1.media.dorkly.cvcdn.com/98/93/8faa22b41bcbe455830907387af3a44b.gif",\n'))
Traceback (most recent call last):
  File "C:\Users\nicos\Desktop\cronanbot\CronanBot\cogs\owner.py", line 931, in _load_cog
    mod_obj = importlib.import_module(cogname)
  File "C:\Users\nicos\AppData\Local\Programs\Python\Python35\lib\importlib\__init__.py", line 126, in import_module
    return _bootstrap._gcd_import(name[level:], package, level)
  File "<frozen importlib._bootstrap>", line 986, in _gcd_import
  File "<frozen importlib._bootstrap>", line 969, in _find_and_load
  File "<frozen importlib._bootstrap>", line 958, in _find_and_load_unlocked
  File "<frozen importlib._bootstrap>", line 673, in _load_unlocked
  File "<frozen importlib._bootstrap_external>", line 658, in exec_module
  File "<frozen importlib._bootstrap_external>", line 764, in get_code
  File "<frozen importlib._bootstrap_external>", line 724, in source_to_code
  File "<frozen importlib._bootstrap>", line 222, in _call_with_frames_removed
  File "C:\Users\nicos\Desktop\cronanbot\CronanBot\cogs\general.py", line 333
    fidget = ["http://1.media.dorkly.cvcdn.com/98/93/8faa22b41bcbe455830907387af3a44b.gif",
                                                                                          ^
IndentationError: unindent does not match any outer indentation level

During handling of the above exception, another exception occurred:

Traceback (most recent call last):
  File "red.py", line 572, in load_cogs
    owner_cog._load_cog(extension)
  File "C:\Users\nicos\Desktop\cronanbot\CronanBot\cogs\owner.py", line 935, in _load_cog
    raise CogLoadError(*e.args)
cogs.owner.CogLoadError: ('unindent does not match any outer indentation level', ('C:\\Users\\nicos\\Desktop\\cronanbot\\CronanBot\\cogs\\general.py', 333, 95, '       fidget = ["http://1.media.dorkly.cvcdn.com/98/93/8faa22b41bcbe455830907387af3a44b.gif",\n'))
[17/07/2017 20:27] ERROR red load_cogs 575: ('unindent does not match any outer indentation level', ('C:\\Users\\nicos\\Desktop\\cronanbot\\CronanBot\\cogs\\general.py', 333, 406, '       fidget = ["http://1.media.dorkly.cvcdn.com/98/93/8faa22b41bcbe455830907387af3a44b.gif", "http://0.media.dorkly.cvcdn.com/20/80/4fcaa14e1215f43b4b791419dca027d9.gif", "https://vhs-talk.s3-us-west-2.amazonaws.com/original/2X/2/2897b1847a18c33315d6d1f0066a6da590181988.gif", "http://fivedollarfidget.com/images/spinhandloop.gif", "http://media.boingboing.net/wp-content/uploads/2017/02/good-spin.gif"]\n'))
Traceback (most recent call last):
  File "C:\Users\nicos\Desktop\cronanbot\CronanBot\cogs\owner.py", line 931, in _load_cog
    mod_obj = importlib.import_module(cogname)
  File "C:\Users\nicos\AppData\Local\Programs\Python\Python35\lib\importlib\__init__.py", line 126, in import_module
    return _bootstrap._gcd_import(name[level:], package, level)
  File "<frozen importlib._bootstrap>", line 986, in _gcd_import
  File "<frozen importlib._bootstrap>", line 969, in _find_and_load
  File "<frozen importlib._bootstrap>", line 958, in _find_and_load_unlocked
  File "<frozen importlib._bootstrap>", line 673, in _load_unlocked
  File "<frozen importlib._bootstrap_external>", line 658, in exec_module
  File "<frozen importlib._bootstrap_external>", line 764, in get_code
  File "<frozen importlib._bootstrap_external>", line 724, in source_to_code
  File "<frozen importlib._bootstrap>", line 222, in _call_with_frames_removed
  File "C:\Users\nicos\Desktop\cronanbot\CronanBot\cogs\general.py", line 333
    fidget = ["http://1.media.dorkly.cvcdn.com/98/93/8faa22b41bcbe455830907387af3a44b.gif", "http://0.media.dorkly.cvcdn.com/20/80/4fcaa14e1215f43b4b791419dca027d9.gif", "https://vhs-talk.s3-us-west-2.amazonaws.com/original/2X/2/2897b1847a18c33315d6d1f0066a6da590181988.gif", "http://fivedollarfidget.com/images/spinhandloop.gif", "http://media.boingboing.net/wp-content/uploads/2017/02/good-spin.gif"]
                                                                                                                                                                                                                                                                                                                                                                                                                 ^
IndentationError: unindent does not match any outer indentation level

During handling of the above exception, another exception occurred:

Traceback (most recent call last):
  File "red.py", line 572, in load_cogs
    owner_cog._load_cog(extension)
  File "C:\Users\nicos\Desktop\cronanbot\CronanBot\cogs\owner.py", line 935, in _load_cog
    raise CogLoadError(*e.args)
cogs.owner.CogLoadError: ('unindent does not match any outer indentation level', ('C:\\Users\\nicos\\Desktop\\cronanbot\\CronanBot\\cogs\\general.py', 333, 406, '       fidget = ["http://1.media.dorkly.cvcdn.com/98/93/8faa22b41bcbe455830907387af3a44b.gif", "http://0.media.dorkly.cvcdn.com/20/80/4fcaa14e1215f43b4b791419dca027d9.gif", "https://vhs-talk.s3-us-west-2.amazonaws.com/original/2X/2/2897b1847a18c33315d6d1f0066a6da590181988.gif", "http://fivedollarfidget.com/images/spinhandloop.gif", "http://media.boingboing.net/wp-content/uploads/2017/02/good-spin.gif"]\n'))
[17/07/2017 20:29] ERROR red load_cogs 575: name 'Spin' is not defined
Traceback (most recent call last):
  File "red.py", line 572, in load_cogs
    owner_cog._load_cog(extension)
  File "C:\Users\nicos\Desktop\cronanbot\CronanBot\cogs\owner.py", line 931, in _load_cog
    mod_obj = importlib.import_module(cogname)
  File "C:\Users\nicos\AppData\Local\Programs\Python\Python35\lib\importlib\__init__.py", line 126, in import_module
    return _bootstrap._gcd_import(name[level:], package, level)
  File "<frozen importlib._bootstrap>", line 986, in _gcd_import
  File "<frozen importlib._bootstrap>", line 969, in _find_and_load
  File "<frozen importlib._bootstrap>", line 958, in _find_and_load_unlocked
  File "<frozen importlib._bootstrap>", line 673, in _load_unlocked
  File "<frozen importlib._bootstrap_external>", line 662, in exec_module
  File "<frozen importlib._bootstrap>", line 222, in _call_with_frames_removed
  File "C:\Users\nicos\Desktop\cronanbot\CronanBot\cogs\general.py", line 38, in <module>
    class General(Spin):
NameError: name 'Spin' is not defined
[17/07/2017 20:36] ERROR red on_command_error 371: Exception in command 'spinner'
Traceback (most recent call last):
  File "lib\discord\ext\commands\core.py", line 50, in wrapped
    ret = yield from coro(*args, **kwargs)
  File "C:\Users\nicos\Desktop\cronanbot\CronanBot\cogs\general.py", line 337, in spinner
    "http://media.boingboing.net/wp-content/uploads/2017/02/good-spin.gif"]
NameError: name 'Spin' is not defined
[17/07/2017 20:38] ERROR red on_command_error 371: Exception in command 'spinner'
Traceback (most recent call last):
  File "lib\discord\ext\commands\core.py", line 50, in wrapped
    ret = yield from coro(*args, **kwargs)
  File "C:\Users\nicos\Desktop\cronanbot\CronanBot\cogs\general.py", line 339, in spinner
    chosenspinner = choice(fidg.spi)
NameError: name 'fidg' is not defined
[17/07/2017 20:40] ERROR red on_command_error 371: Exception in command 'spinner'
Traceback (most recent call last):
  File "lib\discord\ext\commands\core.py", line 50, in wrapped
    ret = yield from coro(*args, **kwargs)
  File "C:\Users\nicos\Desktop\cronanbot\CronanBot\cogs\general.py", line 342, in spinner
    embed.set_image(chosenspinner)
TypeError: set_image() takes 1 positional argument but 2 were given
[17/07/2017 20:41] ERROR red on_command_error 371: Exception in command 'spinner'
Traceback (most recent call last):
  File "lib\discord\ext\commands\core.py", line 50, in wrapped
    ret = yield from coro(*args, **kwargs)
  File "C:\Users\nicos\Desktop\cronanbot\CronanBot\cogs\general.py", line 339, in spinner
    "http://media.boingboing.net/wp-content/uploads/2017/02/good-spin.gif"))
TypeError: choice() takes 2 positional arguments but 6 were given
[17/07/2017 20:46] ERROR red on_command_error 371: Exception in command 'spinner'
Traceback (most recent call last):
  File "lib\discord\ext\commands\core.py", line 50, in wrapped
    ret = yield from coro(*args, **kwargs)
  File "C:\Users\nicos\Desktop\cronanbot\CronanBot\cogs\general.py", line 335, in spinner
    "http://0.media.dorkly.cvcdn.com/20/80/4fcaa14e1215f43b4b791419dca027d9.gif")
TypeError: choice() takes 2 positional arguments but 3 were given
[17/07/2017 21:00] ERROR red on_command_error 371: Exception in command 'spinner'
Traceback (most recent call last):
  File "lib\discord\ext\commands\core.py", line 50, in wrapped
    ret = yield from coro(*args, **kwargs)
  File "C:\Users\nicos\Desktop\cronanbot\CronanBot\cogs\general.py", line 334, in spinner
    cho1 = choice("http://1.media.dorkly.cvcdn.com/98/93/8faa22b41bcbe455830907387af3a44b.gif", "http://0.media.dorkly.cvcdn.com/20/80/4fcaa14e1215f43b4b791419dca027d9.gif")
TypeError: choice() takes 2 positional arguments but 3 were given
[17/07/2017 21:06] ERROR red on_command_error 371: Exception in command 'spinner'
Traceback (most recent call last):
  File "lib\discord\ext\commands\core.py", line 50, in wrapped
    ret = yield from coro(*args, **kwargs)
  File "C:\Users\nicos\Desktop\cronanbot\CronanBot\cogs\general.py", line 335, in spinner
    cho1 = choice("http://1.media.dorkly.cvcdn.com/98/93/8faa22b41bcbe455830907387af3a44b.gif", "http://0.media.dorkly.cvcdn.com/20/80/4fcaa14e1215f43b4b791419dca027d9.gif")
TypeError: choice() takes 2 positional arguments but 3 were given
[17/07/2017 21:08] ERROR red on_command_error 371: Exception in command 'spinner'
Traceback (most recent call last):
  File "lib\discord\ext\commands\core.py", line 50, in wrapped
    ret = yield from coro(*args, **kwargs)
  File "C:\Users\nicos\Desktop\cronanbot\CronanBot\cogs\general.py", line 335, in spinner
    chosenspinner = choice(fidget)
NameError: name 'fidget' is not defined
[17/07/2017 21:08] ERROR red on_command_error 371: Exception in command 'spinner'
Traceback (most recent call last):
  File "lib\discord\ext\commands\core.py", line 50, in wrapped
    ret = yield from coro(*args, **kwargs)
  File "C:\Users\nicos\Desktop\cronanbot\CronanBot\cogs\general.py", line 340, in spinner
    "http://media.boingboing.net/wp-content/uploads/2017/02/good-spin.gif"]))
TypeError: set_image() takes 1 positional argument but 2 were given
[17/07/2017 21:18] ERROR red on_command_error 371: Exception in command 'spinner'
Traceback (most recent call last):
  File "lib\discord\ext\commands\core.py", line 50, in wrapped
    ret = yield from coro(*args, **kwargs)
  File "C:\Users\nicos\Desktop\cronanbot\CronanBot\cogs\general.py", line 340, in spinner
    "http://media.boingboing.net/wp-content/uploads/2017/02/good-spin.gif"]))
TypeError: set_image() takes 1 positional argument but 2 were given
[17/07/2017 21:20] ERROR red on_command_error 371: Exception in command 'spinner'
Traceback (most recent call last):
  File "lib\discord\ext\commands\core.py", line 50, in wrapped
    ret = yield from coro(*args, **kwargs)
  File "C:\Users\nicos\Desktop\cronanbot\CronanBot\cogs\general.py", line 342, in spinner
    embed.set_image(spinchoice)
TypeError: set_image() takes 1 positional argument but 2 were given
[17/07/2017 21:53] ERROR red on_command_error 371: Exception in command 'spinner'
Traceback (most recent call last):
  File "lib\discord\ext\commands\core.py", line 50, in wrapped
    ret = yield from coro(*args, **kwargs)
  File "C:\Users\nicos\Desktop\cronanbot\CronanBot\cogs\general.py", line 340, in spinner
    spinchoice = url(spinchoice)
NameError: name 'url' is not defined
[17/07/2017 21:55] ERROR red on_command_error 371: Exception in command 'spinner'
Traceback (most recent call last):
  File "lib\discord\ext\commands\core.py", line 50, in wrapped
    ret = yield from coro(*args, **kwargs)
  File "C:\Users\nicos\Desktop\cronanbot\CronanBot\cogs\general.py", line 342, in spinner
    embed.set_image(spinchoice)
TypeError: set_image() takes 1 positional argument but 2 were given
[17/07/2017 22:23] ERROR red <module> 636: Fatal exception, attempting graceful logout
Traceback (most recent call last):
  File "red.py", line 616, in <module>
    loop.run_until_complete(main(bot))
  File "C:\Users\nicos\AppData\Local\Programs\Python\Python35\lib\asyncio\base_events.py", line 337, in run_until_complete
    return future.result()
  File "C:\Users\nicos\AppData\Local\Programs\Python\Python35\lib\asyncio\futures.py", line 274, in result
    raise self._exception
  File "C:\Users\nicos\AppData\Local\Programs\Python\Python35\lib\asyncio\tasks.py", line 239, in _step
    result = coro.send(None)
  File "red.py", line 589, in main
    load_cogs(bot)
  File "red.py", line 546, in load_cogs
    bot.load_extension('cogs.owner')
  File "lib\discord\ext\commands\bot.py", line 732, in load_extension
    lib = importlib.import_module(name)
  File "C:\Users\nicos\AppData\Local\Programs\Python\Python35\lib\importlib\__init__.py", line 126, in import_module
    return _bootstrap._gcd_import(name[level:], package, level)
  File "<frozen importlib._bootstrap>", line 986, in _gcd_import
  File "<frozen importlib._bootstrap>", line 969, in _find_and_load
  File "<frozen importlib._bootstrap>", line 958, in _find_and_load_unlocked
  File "<frozen importlib._bootstrap>", line 673, in _load_unlocked
  File "<frozen importlib._bootstrap_external>", line 658, in exec_module
  File "<frozen importlib._bootstrap_external>", line 764, in get_code
  File "<frozen importlib._bootstrap_external>", line 724, in source_to_code
  File "<frozen importlib._bootstrap>", line 222, in _call_with_frames_removed
  File "C:\Users\nicos\Desktop\cronanbot\CronanBot\cogs\owner.py", line 54
    async def load(self, *, cog_name: ):
                                      ^
SyntaxError: invalid syntax
